Workbook

Sheet Index
A8: AusPlay survey results July 2024 - June 2025
A9: Released at: | D9: 13 November 2025
A10: Table name: | D10: Index
E11: Equivalent table number in national data tables
B12: Table number | D12: Table name
A13: Demographics of participants | B13: 1 | D13: Demographics of participants (adults) | E13: 1
B14: 2 | D14: Demographics of participants (children) (organised outside of school hours) | E14: 2
A16: Overall participation | B16: 3 | D16: Organisational nature of activity - overview (adults) | E16: 3
B17: 4 | D17: Organisational nature of activity - detail (adults) | E17: 4
B18: 5 | D18: Organised activity by type of entity (adults) | E18: 5
B19: 6 | D19: Organised activity by type of entity (children) | E19: 6
B20: 7 | D20: Places where activity took place (adults) | E20: 7
B21: 8 | D21: Places where activity took place (children) | E21: 8
B22: 9 | D22: Frequency of participation (adults) | E22: 9
B23: 10 | D23: Frequency of participation (children) | E23: 10
B24: 11 | D24: Motivations for participation (adults) | E24: 12
B25: 12 | D25: Barriers to participation (adults) | E25: 13
B26: 13 | D26: Barriers to participation (children) | E26: 14
B27: 14 | D27: Sport or non-sport related participation (adults) | E27: 15
B28: 15 | D28: Sport or non-sport related participation (children) | E28: 16
... B37: 24 | D37: Volunteers in non-playing roles by activity - top roles and top 5 activities (adults) | E37: 27
A39: Demographics of non-participants | B39: 25 | D39: Demographics of non-participants (adults) | E39: 30
B40: 26 | D40: Demographics of non-participants (children) | E40: 31
A42: Margin of error tables | B42: 27 | D42: Margins of error | E42: 38
A44: Key terms and definitions | B44: 28 | D44: Key terms and definitions | E44: 39

Sheet 1
A8: AusPlay survey results July 2024 - June 2025
A9: Released at: | B9: 13 November 2025
A10: Table number: | B10: 1
A11: Table name: | B11: Demographics of participants (adults)
A12: Base: | B12: Adult population
C13: At least once per year participation | K13: At least once per week participation | S13: At least three times per week participation
C14: Participation rate | G14: Estimated number of participants | K14: Participation rate | O14: Estimated number of participants | S14: Participation rate | W14: Estimated number of participants
C15: Total | D15: Males | E15: Females | G15: Total# | H15: Males | I15: Females | K15: Total | L15: Males | M15: Females | O15: Total# | P15: Males | Q15: Females | S15: Total | T15: Males | U15: Females | W15: Total# | X15: Males | Y15: Females
A16: Total | C16: 0.86963983 | D16: 0.87734998 | E16: 0.8644377 | G16: 5015652.8 | H16: 2468235.6 | I16: 2520330.1 | K16: 0.69587655 | L16: 0.69330247 | M16: 0.70039246 | O16: 4013472.1 | P16: 1950457.5 | Q16: 2042044.5 | S16: 0.50051291 | T16: 0.48381292 | U16: 0.51785436 | W16: 2886711.1 | X16: 1361103.7 | Y16: 1509841.5
A17: Age group
B18: 15-17 | C18: 0.84583468 | D18: 0.81985642 | E18: 0.88504676 | G18: 203601.17 | H18: 81119.411 | I18: 122481.76 | K18: 0.64605555 | L18: 0.6328725 | M18: 0.67124489 | O18: 155512.26 | P18: 62618.578 | Q18: 92893.684 | S18: 0.44760347 | T18: 0.46141719 | U18: 0.4486489 | W18: 107742.79 | X18: 45654.202 | Y18: 62088.59
B19: 18-24 | C19: 0.88919859 | D19: 0.88133157 | E19: 0.90036213 | G19: 603392.95 | H19: 321407.44 | I19: 274016 | K19: 0.6971593 | L19: 0.6706821 | M19: 0.72796411 | O19: 473078.8 | P19: 244586.97 | Q19: 221548.43 | S19: 0.47908839 | T19: 0.43906984 | U19: 0.52569605 | W19: 325100.1 | X19: 160121.7 | Y19: 159990.21
B20: 25-34 | C20: 0.91865092 | D20: 0.92020703 | E20: 0.91694021 | G20: 970562.03 | H20: 465225.36 | I20: 498542.5 | K20: 0.72103126 | L20: 0.69533249 | M20: 0.7457116 | O20: 761775.28 | P20: 351536.45 | Q20: 405445.12 | S20: 0.51492309 | T20: 0.47116949 | U20: 0.55700452 | W20: 544020.35 | X20: 238207.26 | Y20: 302844.64
B21: 35-44 | C21: 0.89233389 | D21: 0.88795492 | E21: 0.89883808 | G21: 896984.71 | H21: 449706.14 | I21: 443003.41 | K21: 0.69155327 | L21: 0.6721466 | M21: 0.71238105 | O21: 695157.63 | P21: 340409.68 | Q21: 351105.77 | S21: 0.4702791 | T21: 0.44343327 | U21: 0.49610314 | W21: 472730.19 | X21: 224577.46 | Y21: 244510.54
B22: 45-54 | C22: 0.89145479 | D22: 0.90325368 | E22: 0.87860481 | G22: 769097.39 | H22: 384156.93 | I22: 379973.22 | K22: 0.72534802 | L22: 0.72477687 | M22: 0.72731465 | O22: 625789.75 | P22: 308250.13 | Q22: 314544.25 | S22: 0.53644837 | T22: 0.51398847 | U22: 0.55894361 | W22: 462817.69 | X22: 218601.08 | Y22: 241728.25
B23: 55-64 | C23: 0.8752102 | D23: 0.87325812 | E23: 0.87649254 | G23: 652990.96 | H23: 323892.01 | I23: 327132.25 | K23: 0.74021626 | L23: 0.73669691 | M23: 0.74364566 | O23: 552272.5 | P23: 273241.37 | Q23: 277549.97 | S23: 0.5777315 | T23: 0.56162514 | U23: 0.59411259 | W23: 431043.24 | X23: 208307.13 | Y23: 221739.92
B24: 65+ | C24: 0.78038467 | D24: 0.81769266 | E24: 0.75356774 | G24: 919023.6 | H24: 442728.31 | I24: 475181 | K24: 0.63676215 | L24: 0.68302491 | M24: 0.60097093 | O24: 749885.89 | P24: 369814.33 | Q24: 378957.26 | S24: 0.46130398 | T24: 0.4906116 | U24: 0.43918547 | W24: 543256.77 | X24: 265634.82 | Y24: 276939.39
A25: Remoteness
B26: Major cities | C26: 0.87658462 | D26: 0.88840753 | E26: 0.86825896 | G26: 3901487 | H26: 1925550.6 | I26: 1957141.6 | K26: 0.7017332 | L26: 0.70537954 | M26: 0.70125271 | O26: 3123261.5 | P26: 1528852.4 | Q26: 1580693 | S26: 0.50191156 | T26: 0.49291365 | U26: 0.51311205 | W26: 2233898.9 | X26: 1068350 | Y26: 1156605.3
B27: Inner regional | C27: 0.84774107 | D27: 0.84160394 | E27: 0.85342258 | G27: 916261.95 | H27: 447348.05 | I27: 461592.14 | K27: 0.67431061 | L27: 0.6475125 | M27: 0.69862069 | O27: 728813.52 | P27: 344180.25 | Q27: 377864.18 | S27: 0.49778063 | T27: 0.45691556 | U27: 0.5339672 | W27: 538015.05 | X27: 242869.92 | Y27: 288807.76
B28: Outer regional | C28: 0.83721306 | D28: 0.83018759 | E28: 0.84241682 | G28: 195395.12 | H28: 92828.236 | I28: 101596.4 | K28: 0.68282113 | L28: 0.67423019 | M28: 0.69225989 | O28: 159361.96 | P28: 75389.708 | Q28: 83487.31 | S28: 0.48518268 | T28: 0.43215824 | U28: 0.53422781 | W28: 113235.61 | X28: 48322.196 | Y28: 64428.466
B29: Remote or very remote | C29: 1 | D29: 1 | E29: 0 | G29: 2508.7301 | H29: 2508.7301 | I29: 0 | K29: 0.81122657 | L29: 0.81122657 | M29: 0 | O29: 2035.1485 | P29: 2035.1485 | Q29: 0 | S29: 0.62245314 | T29: 0.62245314 | U29: 0 | W29: 1561.5669 | X29: 1561.5669 | Y29: 0
A30: Employment status
B31: Employed full-time | C31: 0.91182495 | D31: 0.91345778 | E31: 0.91025618 | G31: 2380731.8 | H31: 1409027.2 | I31: 964631.57 | K31: 0.72861135 | L31: 0.71459382 | M31: 0.75053382 | O31: 1902369.8 | P31: 1102275.5 | Q31: 795367.98 | S31: 0.52012828 | T31: 0.49620235 | U31: 0.55704218 | W31: 1358030.4 | X31: 765402.22 | Y31: 590317.85
B32: Employed part-time | C32: 0.88617522 | D32: 0.85854429 | E32: 0.90317732 | G32: 772508.71 | H32: 259305.4 | I32: 507728.18 | K32: 0.70713115 | L32: 0.66570814 | M32: 0.73116798 | O32: 616429.97 | P32: 201063.27 | Q32: 411031.79 | S32: 0.5108512 | T32: 0.46717878 | U32: 0.53511131 | W32: 445326.15 | X32: 141101.61 | Y32: 300817
B33: Employed casual | C33: 0.91392069 | D33: 0.92111811 | E33: 0.91037389 | G33: 305409.63 | H33: 117269.4 | I33: 184675.55 | K33: 0.76096055 | L33: 0.78104784 | M33: 0.74630319 | O33: 254294.14 | P33: 99436.769 | Q33: 151392.69 | S33: 0.53581952 | T33: 0.51754668 | U33: 0.54542333 | W33: 179057.59 | X33: 65889.908 | Y33: 110642.84
B34: Total employed | C34: 0.90615029 | D34: 0.90554129 | E34: 0.90808846 | G34: 3458650.2 | H34: 1785602 | I34: 1657035.3 | K34: 0.72653773 | L34: 0.71139658 | M34: 0.7440974 | O34: 2773093.9 | P34: 1402775.5 | Q34: 1357792.5 | S34: 0.51938329 | T34: 0.49313491 | U34: 0.54899419 | W34: 1982414.1 | X34: 972393.74 | Y34: 1001777.7
B35: Full-time student | C35: 0.90542577 | D35: 0.90724917 | E35: 0.91543538 | G35: 270095.49 | H35: 132096.77 | I35: 135494.25 | K35: 0.71709577 | L35: 0.68136427 | M35: 0.76153801 | O35: 213915.19 | P35: 99207.606 | Q35: 112715.79 | S35: 0.50330625 | T35: 0.46493645 | U35: 0.54356151 | W35: 150140.13 | X35: 67695.407 | Y35: 80452.932
B36: Engaged in home duties | C36: 0.80619077 | D36: 0.70855379 | E36: 0.8228526 | G36: 153533.14 | H36: 20282.99 | I36: 132692.52 | K36: 0.64374443 | L36: 0.58569696 | M36: 0.6528168 | O36: 122596.42 | P36: 16766.102 | Q36: 105272.69 | S36: 0.48560917 | T36: 0.3988446 | U36: 0.49923242 | W36: 92480.718 | X36: 11417.285 | Y36: 80505.803
B37: Unemployed | C37: 0.78256518 | D37: 0.7667054 | E37: 0.79481202 | G37: 191914.34 | H37: 86225.733 | I37: 103194.87 | K37: 0.57010446 | L37: 0.59182096 | M37: 0.55314225 | O37: 139811 | P37: 66557.763 | Q37: 71817.536 | S37: 0.43270667 | T37: 0.4197865 | U37: 0.44263603 | W37: 106115.91 | X37: 47210.309 | Y37: 57469.898
B38: Retired or on a pension | C38: 0.77773585 | D38: 0.81047546 | E38: 0.75436735 | G38: 891240.81 | H38: 418531.27 | I38: 468914.06 | K38: 0.63848153 | L38: 0.67248053 | M38: 0.61228765 | O38: 731663.33 | P38: 347270.39 | Q38: 380597.45 | S38: 0.46631252 | T38: 0.48817378 | U38: 0.4494842 | W38: 534367.48 | X38: 252093.99 | Y38: 279398.97
A39: Highest education completed
B40: University degree or higher (including postgraduate diploma) | C40: 0.93005806 | D40: 0.92570662 | E40: 0.93509455 | G40: 2292689.5 | H40: 1189383 | I40: 1093277.6 | K40: 0.77031153 | L40: 0.7636459 | M40: 0.77879662 | O40: 1898897.7 | P40: 981161.26 | Q40: 910539.91 | S40: 0.56435612 | T40: 0.54642987 | U40: 0.58476873 | W40: 1391196.3 | X40: 702073.85 | Y40: 683689.75
B41: Undergraduate diploma or associate diploma | C41: 0.86843374 | D41: 0.87201224 | E41: 0.87033897 | G41: 690329.26 | H41: 338015.12 | I41: 348864.79 | K41: 0.69152227 | L41: 0.67818051 | M41: 0.70978854 | O41: 549700.04 | P41: 262880.79 | Q41: 284510.1 | S41: 0.49263568 | T41: 0.46354264 | U41: 0.52547208 | W41: 391602.5 | X41: 179681.45 | Y41: 210629.09
B42: Certificate, trade qualification or apprenticeship | C42: 0.83550994 | D42: 0.84393972 | E42: 0.82817543 | G42: 780273.79 | H42: 355564.34 | I42: 420854.29 | K42: 0.64887467 | L42: 0.6310034 | M42: 0.66172844 | O42: 605977.11 | P42: 265851.11 | Q42: 336270.85 | S42: 0.45947396 | T42: 0.41422432 | U42: 0.49618206 | W42: 429097.81 | X42: 174518.86 | Y42: 252145.07
B43: Highest level of secondary school | C43: 0.84233493 | D43: 0.84041631 | E43: 0.84737292 | G43: 772700.45 | H43: 374369.4 | I43: 393452.44 | K43: 0.66310925 | L43: 0.64450096 | M43: 0.68353738 | O43: 608291.07 | P43: 287097.52 | Q43: 317380.27 | S43: 0.46953712 | T43: 0.44539327 | U43: 0.49318025 | W43: 430721.23 | X43: 198403.59 | Y43: 228993.6
B44: Did not complete highest level of school | C44: 0.68150517 | D44: 0.77798972 | E44: 0.61913844 | G44: 249417.18 | H44: 106412.43 | I44: 139305.9 | K44: 0.4904229 | L44: 0.54244116 | M44: 0.45631542 | O44: 179484.91 | P44: 74194.404 | Q44: 102670.79 | S44: 0.34731571 | T44: 0.3834435 | U44: 0.32019582 | W44: 127110.56 | X44: 52446.909 | Y44: 72043.932
B45: Still at secondary school | C45: 0.87876513 | D45: 0.88466411 | E45: 0.90426776 | G45: 175042.07 | H45: 77963.821 | I45: 96565.583 | K45: 0.68491443 | L45: 0.7176462 | M45: 0.68051446 | O45: 136428.77 | P45: 63244.839 | Q45: 72671.258 | S45: 0.47014074 | T45: 0.52399568 | U45: 0.44451341 | W45: 93647.787 | X45: 46178.775 | Y45: 47469.012
A46: Household structure
B47: Younger family (most children under 15 years) | C47: 0.91363686 | D47: 0.92719435 | E47: 0.90425039 | G47: 985151.1 | H47: 498600.73 | I47: 484958.18 | K47: 0.67225558 | L47: 0.64961653 | M47: 0.69833454 | O47: 724875.89 | P47: 349332.67 | Q47: 374523.53 | S47: 0.42528295 | T47: 0.4028978 | U47: 0.45106876 | W47: 458571.66 | X47: 216659.15 | Y47: 241912.51
...

Sheet 2
A8: =Index!A8 -> AusPlay survey results July 2024 - June 2025
A9: Released at: | B9: =Index!D9 -> 13 November 2025
A10: Table number: | B10: =Index!B14 -> 2
A11: Table name: | B11: =Index!D14 -> Demographics of participants (children) (organised outside of school hours)
A12: Base: | B12: Child population
C13: At least once per year participation
C14: Participation rate | G14: Estimated number of participants
C15: Total | D15: Males | E15: Females | G15: Total# | H15: Males | I15: Females
A16: Total | C16: 0.73214143 | D16: 0.73432868 | E16: 0.73189896 | G16: 895893.56 | H16: 478087.93 | I16: 417206.92
A17: Age group
B18: 0-4 | C18: 0.49966693 | D18: 0.47976559 | E18: 0.52100406 | G18: 190197.74 | H18: 97826.679 | I18: 91772.349
B19: 5-8 | C19: 0.82201643 | D19: 0.82510263 | E19: 0.82368095 | G19: 275470.33 | H19: 140638.57 | I19: 134831.76
B20: 9-11 | C20: 0.85018509 | D20: 0.87466939 | E20: 0.82780859 | G20: 211466.22 | H20: 113824.18 | I20: 97642.039
B21: 12-14 | C21: 0.84408334 | D21: 0.85830895 | E21: 0.82821936 | G21: 218759.28 | H21: 125798.5 | I21: 92960.778
A22: Remoteness
B23: Major cities | C23: 0.73663157 | D23: 0.74913361 | E23: 0.72530239 | G23: 700762.27 | H23: 378656.7 | I23: 321506.85
B24: Inner regional | C24: 0.72690454 | D24: 0.68018163 | E24: 0.7789363 | G24: 165120.12 | H24: 81406.374 | I24: 83713.746
B25: Outer regional | C25: 0.66395816 | D25: 0.69562799 | E25: 0.62141442 | G25: 30011.176 | H25: 18024.853 | I25: 11986.322
B26: Remote or very remote | C26: 0 | D26: 0 | E26: 0 | G26: 0 | H26: 0 | I26: 0
A27: Household structure
B28: Younger family (most children under 15 years) | C28: 0.71811855 | D28: 0.71670231 | E28: 0.72179954 | G28: 743080 | H28: 395110.61 | I28: 347370.68
B29: Mature family (most children 15 years or over) | C29: 0.76824435 | D29: 0.80154546 | E29: 0.7209045 | G29: 58228.976 | H29: 35664.746 | I29: 22564.23
B30: Mid family (equal number of children 15 years and over and under 15 years) | C30: 0.83623615 | D30: 0.85603039 | E30: 0.82244858 | G30: 94584.587 | H30: 47312.576 | I30: 47272.011
A31: Aboriginal or Torres Strait Islander origin of parent/guardian interviewed^
B32: Yes | C32: 0.7684783 | D32: 0.81327073 | E32: 0.72922135 | G32: 60538.928 | H32: 33240.506 | I32: 27298.422
B33: No | C33: 0.72998407 | D33: 0.72751817 | E33: 0.73457735 | G33: 816298.19 | H33: 431777.97 | I33: 383921.51
B34: Refused / don't know | C34: 0.71524812 | D34: 0.7831938 | E34: 0.60136056 | G34: 19056.446 | H34: 13069.454 | I34: 5986.9921
A35: Language spoken at home by parent/guardian interviewed^
B36: Speaks only English at home | C36: 0.72538148 | D36: 0.72310327 | E36: 0.72872754 | G36: 690959.07 | H36: 370397.57 | I36: 319962.79
B37: Speaks language other than English at home | C37: 0.75812506 | D37: 0.77708446 | E37: 0.74031286 | G37: 195372.56 | H37: 102647.05 | I37: 92725.511
A38: Annual household income~^
B39: <$40,000 | C39: 0.58679854 | D39: 0.65186485 | E39: 0.54542137 | G39: 35155.6 | H39: 17329.704 | I39: 17825.896
B40: $40,000 - $69,999 | C40: 0.72075624 | D40: 0.74800837 | E40: 0.69666816 | G40: 66183.793 | H40: 37315.804 | I40: 28867.989
B41: $70,000 - $99,999 | C41: 0.69245134 | D41: 0.68732266 | E41: 0.70093041 | G41: 117731.3 | H41: 60048.877 | I41: 57682.427
B42: $100,000 - $149,999 | C42: 0.74443802 | D42: 0.74052585 | E42: 0.74848263 | G42: 262733.88 | H42: 146866.65 | I42: 115268.52
B43: $150,000 - $199,999 | C43: 0.68385274 | D43: 0.65888806 | E43: 0.71608741 | G43: 139190.48 | H43: 75577.191 | I43: 63613.287
B44: $200,000+ | C44: 0.81950357 | D44: 0.83945316 | E44: 0.80011713 | G44: 189379.27 | H44: 95606.111 | I44: 93773.163
B45: Not stated | C45: 0.74789595 | D45: 0.75204437 | E45: 0.74978835 | G45: 85519.237 | H45: 45343.594 | I45: 40175.644
A47: NB. Please note that for children 0-14 years, data was collected via the child's parent/guardian for organised participation outside of school hours
A48: NB. Estimated participant numbers have not been rounded but users must remember that they are estimates and are subject to margins of error. Refer to sheet number 27 for margin of error and relative margin of error statistics.
...

Sheet 3
A8: =Index!A8 -> AusPlay survey results July 2024 - June 2025
A9: Released at: | C9: 13 November 2025
A10: Table number: | C10: 3
A11: Table name: | C11: Organisational nature of activity - overview (adults)
A12: Base: | C12: Adult population
E13: Organisational nature of activity
C14: Total | E14: Informal only | F14: Mix of informal and organised | G14: Organised only | H14: Don't know | I14: Total informal | J14: Total organised
E15: (a) | F15: (b) | G15: (c) | H15: (d) | I15: (a + b) | J15: (b + c)
C16: Participation rate
A17: All# | B17: Total | C17: 0.86963983 | E17: 0.42890993 | F17: 0.36708204 | G17: 0.06694066 | H17: 0.006707196 | I17: 0.79599197 | J17: 0.4340227
B18: 15-17 | C18: 0.84583468 | E18: 0.21085199 | F18: 0.54794244 | G18: 0.052410273 | H18: 0.034629981 | I18: 0.75879443 | J18: 0.60035271
B19: 18-24 | C19: 0.88919859 | E19: 0.33648746 | F19: 0.48431627 | G19: 0.065496993 | H19: 0.0028978696 | I19: 0.82080373 | J19: 0.54981326
B20: 25-34 | C20: 0.91865092 | E20: 0.3770978 | F20: 0.46759545 | G20: 0.06819255 | H20: 0.005765119 | I20: 0.84469325 | J20: 0.535788
B21: 35-44 | C21: 0.89233389 | E21: 0.4392554 | F21: 0.36511301 | G21: 0.082833669 | H21: 0.005131807 | I21: 0.80436841 | J21: 0.44794668
B22: 45-54 | C22: 0.89145479 | E22: 0.51446195 | F22: 0.3242638 | G22: 0.048763049 | H22: 0.0039659985 | I22: 0.83872575 | J22: 0.37302685
B23: 55-64 | C23: 0.8752102 | E23: 0.53538838 | F23: 0.28875054 | G23: 0.043577101 | H23: 0.0074941824 | I23: 0.82413892 | J23: 0.33232764
B24: 65+ | C24: 0.78038467 | E24: 0.43425343 | F24: 0.25506469 | G24: 0.084172258 | H24: 0.0068942862 | I24: 0.68931812 | J24: 0.33923695
A26: Males | B26: Total | C26: 0.87734998 | E26: 0.44169811 | F26: 0.36410883 | G26: 0.065213506 | H26: 0.0063295288 | I26: 0.80580694 | J26: 0.42932234
B27: 15-17 | C27: 0.81985642 | E27: 0.15703661 | F27: 0.60428421 | G27: 0.031338435 | H27: 0.027197177 | I27: 0.76132081 | J27: 0.63562264
B28: 18-24 | C28: 0.88133157 | E28: 0.32876131 | F28: 0.47759893 | G28: 0.071064521 | H28: 0.0039068081 | I28: 0.80636024 | J28: 0.54866345
B29: 25-34 | C29: 0.92020703 | E29: 0.38129064 | F29: 0.46042584 | G29: 0.07389466 | H29: 0.0045958882 | I29: 0.84171648 | J29: 0.5343205
B30: 35-44 | C30: 0.88795492 | E30: 0.44169799 | F30: 0.34807441 | G30: 0.090208515 | H30: 0.0079739939 | I30: 0.78977241 | J30: 0.43828293
B31: 45-54 | C31: 0.90325368 | E31: 0.53869578 | F31: 0.30475072 | G31: 0.053906312 | H31: 0.0059008748 | I31: 0.84344649 | J31: 0.35865703
B32: 55-64 | C32: 0.87325812 | E32: 0.54025084 | F32: 0.28203281 | G32: 0.045713953 | H32: 0.0052605224 | I32: 0.82228365 | J32: 0.32774677
B33: 65+ | C33: 0.81769266 | E33: 0.48248767 | F33: 0.27169076 | G33: 0.058216697 | H33: 0.0052975354 | I33: 0.75417843 | J33: 0.32990746
A35: Females | B35: Total | C35: 0.8644377 | E35: 0.4168461 | F35: 0.37166088 | G35: 0.069154196 | H35: 0.0067765193 | I35: 0.78850698 | J35: 0.44081507
B36: 15-17 | C36: 0.88504676 | E36: 0.2544727 | F36: 0.52103031 | G36: 0.068754625 | H36: 0.040789123 | I36: 0.77550301 | J36: 0.58978493
B37: 18-24 | C37: 0.90036213 | E37: 0.33935105 | F37: 0.49996171 | G37: 0.059269497 | H37: 0.0017798797 | I37: 0.83931275 | J37: 0.5592312
B38: 25-34 | C38: 0.91694021 | E38: 0.37039181 | F38: 0.47704141 | G38: 0.063798419 | H38: 0.0057085731 | I38: 0.84743321 | J38: 0.54083982
B39: 35-44 | C39: 0.89883808 | E39: 0.43634748 | F39: 0.38397116 | G39: 0.076246761 | H39: 0.0022726681 | I39: 0.82031865 | J39: 0.46021792
B40: 45-54 | C40: 0.87860481 | E40: 0.49310941 | F40: 0.34133574 | G40: 0.043105286 | H40: 0.0010543762 | I40: 0.83444515 | J40: 0.38444102
B41: 55-64 | C41: 0.87649254 | E41: 0.53077722 | F41: 0.29427871 | G41: 0.041683206 | H41: 0.0097533992 | I41: 0.82505593 | J41: 0.33596192
B42: 65+ | C42: 0.75356774 | E42: 0.39495702 | F42: 0.24307167 | G42: 0.10721203 | H42: 0.0083270205 | I42: 0.63802869 | J42: 0.3502837
C43: Estimated number of participants
A44: All# | B44: Total | C44: 5015652.8 | E44: 2473740.6 | F44: 2117147.8 | G44: 386080.65 | H44: 38683.792 | I44: 4590888.4 | J44: 2503228.5
B45: 15-17 | C45: 203601.17 | E45: 50754.258 | F45: 131895.42 | G45: 12615.696 | H45: 8335.7952 | I45: 182649.68 | J45: 144511.12
B46: 18-24 | C46: 603392.95 | E46: 228333.87 | F46: 328647.64 | G46: 44444.991 | H46: 1966.4382 | I46: 556981.52 | J46: 373092.63
B47: 25-34 | C47: 970562.03 | E47: 398406.84 | F47: 494018.32 | G47: 72045.973 | H47: 6090.8942 | I47: 892425.16 | J47: 566064.3
B48: 35-44 | C48: 896984.71 | E48: 441544.79 | F48: 367015.97 | G48: 83265.396 | H48: 5158.5539 | I48: 808560.76 | J48: 450281.37
B49: 45-54 | C49: 769097.39 | E49: 443849.03 | F49: 279756.69 | G49: 42070.034 | H49: 3421.642 | I49: 723605.72 | J49: 321826.73
...

Sheet 4
A8: =Index!A8 -> AusPlay survey results July 2024 - June 2025
A9: Released at: | C9: 13 November 2025
A10: Table number: | C10: 4
A11: Table name: | C11: Organisational nature of activity - detail (adults)
A12: Base: | C12: Adult population
E13: Informal participation | H13: Organised participation | S13: Other
C14: Total | E14: Informally by myself | F14: Informally with family and friends | H14: Sports club or association | I14: Gym/fitness club/sports/ leisure centre | J14: Private or commercial business | K14: Community organisation | L14: Individual personal trainer or coach | M14: Event (e.g. marathon, parkrun) | N14: Recreation club or association | O14: Less formal group (e.g. social group) | P14: Work | Q14: Educational institution | S14: Other | T14: Don't know
C15: Participation rate
A16: All# | B16: Total | C16: 0.86963983 | E16: 0.69950717 | F16: 0.50707375 | H16: 0.13999695 | I16: 0.11429196 | J16: 0.11229376 | K16: 0.07460163 | L16: 0.070460771 | M16: 0.063409976 | N16: 0.065158253 | O16: 0.048988487 | P16: 0.046018059 | Q16: 0.044744842 | S16: 0.014171424 | T16: 0.012742963
B17: 15-17 | C17: 0.84583468 | E17: 0.6479657 | F17: 0.60810517 | H17: 0.2369585 | I17: 0.10024092 | J17: 0.076429833 | K17: 0.12257092 | L17: 0.067718353 | M17: 0.086748114 | N17: 0.09558657 | O17: 0.098657037 | P17: 0.045714415 | Q17: 0.27054284 | S17: 0.024051304 | T17: 0.068162694
B18: 18-24 | C18: 0.88919859 | E18: 0.71750543 | F18: 0.61087701 | H18: 0.23475734 | I18: 0.1315749 | J18: 0.13171769 | K18: 0.09922936 | L18: 0.10751977 | M18: 0.098525485 | N18: 0.10880481 | O18: 0.058736357 | P18: 0.059167243 | Q18: 0.12012419 | S18: 0.0038543278 | T18: 0.017235061
B19: 25-34 | C19: 0.91865092 | E19: 0.74652175 | F19: 0.57750683 | H19: 0.17954233 | I19: 0.17111296 | J19: 0.17936667 | K19: 0.10423881 | L19: 0.10774985 | M19: 0.098398332 | N19: 0.092267354 | O19: 0.055175782 | P19: 0.09584664 | Q19: 0.057760757 | S19: 0.0096514544 | T19: 0.016830559
B20: 35-44 | C20: 0.89233389 | E20: 0.71827903 | F20: 0.49528896 | H20: 0.13209301 | I20: 0.11533463 | J20: 0.13994641 | K20: 0.060043821 | L20: 0.064149244 | M20: 0.073980993 | N20: 0.059833415 | O20: 0.039351112 | P20: 0.050170723 | Q20: 0.029914127 | S20: 0.0074041933 | T20: 0.011351057
B21: 45-54 | C21: 0.89145479 | E21: 0.74623568 | F21: 0.50011619 | H21: 0.10639953 | I21: 0.091813734 | J21: 0.09575606 | K21: 0.047143617 | L21: 0.053081357 | M21: 0.064586823 | N21: 0.038522045 | O21: 0.042633447 | P21: 0.044287416 | Q21: 0.013823881 | S21: 0.015198725 | T21: 0.0074166429
B22: 55-64 | C22: 0.8752102 | E22: 0.74421363 | F22: 0.50430096 | H22: 0.087067694 | I22: 0.089229238 | J22: 0.087991421 | K22: 0.043513078 | L22: 0.047890956 | M22: 0.03519148 | N22: 0.032952641 | O22: 0.04618946 | P22: 0.023790412 | Q22: 0.005853597 | S22: 0.01901255 | T22: 0.0049744691
B23: 65+ | C23: 0.78038467 | E23: 0.57891345 | F23: 0.38033563 | H23: 0.094991581 | I23: 0.087685353 | J23: 0.052167453 | K23: 0.076255294 | L23: 0.048632696 | M23: 0.015009001 | N23: 0.053931025 | O23: 0.042323838 | P23: 0.0056061834 | Q23: 0.0034315428 | S23: 0.02410849 | T23: 0.0051715763
A25: Males | B25: Total | C25: 0.87734998 | E25: 0.7043859 | F25: 0.50149312 | H25: 0.18163806 | I25: 0.091070638 | J25: 0.078125531 | K25: 0.081764683 | L25: 0.066107034 | M25: 0.067575349 | N25: 0.077478785 | O25: 0.051702894 | P25: 0.05583289 | Q25: 0.052810091 | S25: 0.0091104394 | T25: 0.014103448
B26: 15-17 | C26: 0.81985642 | E26: 0.60335897 | F26: 0.61999149 | H26: 0.22257342 | I26: 0.09403515 | J26: 0.051415591 | K26: 0.1248395 | L26: 0.068459882 | M26: 0.06572958 | N26: 0.1099877 | O26: 0.10863404 | P26: 0.020077156 | Q26: 0.32323802 | S26: 0.041491322 | T26: 0.041491322
B27: 18-24 | C27: 0.88133157 | E27: 0.67417756 | F27: 0.58522429 | H27: 0.27517409 | I27: 0.11818611 | J27: 0.085346586 | K27: 0.11331675 | L27: 0.11238997 | M27: 0.10686851 | N27: 0.12110459 | O27: 0.070340582 | P27: 0.066141161 | Q27: 0.1378947 | S27: 0.0014593733 | T27: 0.018113091
B28: 25-34 | C28: 0.92020703 | E28: 0.73211225 | F28: 0.54109846 | H28: 0.23658044 | I28: 0.14903182 | J28: 0.12566921 | K28: 0.12918985 | L28: 0.10738437 | M28: 0.10475806 | N28: 0.12616724 | O28: 0.055862571 | P28: 0.12873199 | Q28: 0.072929351 | S28: 0.0034249193 | T28: 0.018095603
B29: 35-44 | C29: 0.88795492 | E29: 0.70775922 | F29: 0.47723342 | H29: 0.16994079 | I29: 0.10766307 | J29: 0.085458911 | K29: 0.069189835 | L29: 0.055336431 | M29: 0.075449248 | N29: 0.071573292 | O29: 0.040251034 | P29: 0.061794877 | Q29: 0.038115179 | S29: 0.0052144367 | T29: 0.017105831
B30: 45-54 | C30: 0.90325368 | E30: 0.75390408 | F30: 0.48079939 | H30: 0.13028131 | I30: 0.074921278 | J30: 0.07241366 | K30: 0.054393823 | L30: 0.045027298 | M30: 0.064154956 | N30: 0.044720538 | O30: 0.04101965 | P30: 0.050477972 | Q30: 0.015362332 | S30: 0.0058230554 | T30: 0.0081962508
B31: 55-64 | C31: 0.87325812 | E31: 0.74408211 | F31: 0.50357173 | H31: 0.11694859 | I31: 0.057671053 | J31: 0.059791721 | K31: 0.045704863 | L31: 0.04202668 | M31: 0.034599581 | N31: 0.044360918 | O31: 0.059116485 | P31: 0.024967922 | Q31: 0.0066940806 | S31: 0.0091840028 | T31: 0.0064544096
B32: 65+ | C32: 0.81769266 | E32: 0.64805962 | F32: 0.42398325 | H32: 0.15545086 | I32: 0.038188954 | J32: 0.043935348 | K32: 0.066322476 | L32: 0.039089322 | M32: 0.02463846 | N32: 0.050633666 | O32: 0.038886808 | P32: 0.007127369 | Q32: 0.0020482624 | S32: 0.019831443 | T32: 0.0097417568
A34: Females | B34: Total | C34: 0.8644377 | E34: 0.69566263 | F34: 0.51383389 | H34: 0.10122022 | I34: 0.13704474 | J34: 0.14576029 | K34: 0.068538912 | L34: 0.075082883 | M34: 0.059911789 | N34: 0.053768047 | O34: 0.045709409 | P34: 0.03665636 | Q34: 0.03738591 | S34: 0.018742677 | T34: 0.011181966
B35: 15-17 | C35: 0.88504676 | E35: 0.69566833 | F35: 0.6144449 | H35: 0.25302513 | I35: 0.1071237 | J35: 0.096178931 | K35: 0.12393976 | L35: 0.068840541 | M35: 0.10389221 | N35: 0.087622685 | O35: 0.093931147 | P35: 0.065159479 | Q35: 0.23946923 | S35: 0.012169247 | T35: 0.088894853
B36: 18-24 | C36: 0.90036213 | E36: 0.76738221 | F36: 0.64433346 | H36: 0.19070559 | I36: 0.14851089 | J36: 0.18821374 | K36: 0.085464764 | L36: 0.10506027 | M36: 0.09162214 | N36: 0.095795932 | O36: 0.043709877 | P36: 0.052668533 | Q36: 0.10097588 | S36: 0.0051606566 | T36: 0.016724156
B37: 25-34 | C37: 0.91694021 | E37: 0.75858533 | F37: 0.60976048 | H37: 0.1288957 | I37: 0.19299196 | J37: 0.23078626 | K37: 0.082425887 | L37: 0.10862464 | M37: 0.093794917 | N37: 0.061973862 | O37: 0.054435701 | P37: 0.065764888 | Q37: 0.044425235 | S37: 0.014669958 | T37: 0.014657825
B38: 35-44 | C38: 0.89883808 | E38: 0.72901044 | F38: 0.51662278 | H38: 0.094782458 | I38: 0.12359365 | J38: 0.197611 | K38: 0.051364184 | L38: 0.072968448 | M38: 0.072295001 | N38: 0.048485878 | O38: 0.036882001 | P38: 0.038826464 | Q38: 0.02184494 | S38: 0.0097429328 | T38: 0.0055734518
B39: 45-54 | C39: 0.87860481 | E39: 0.73904837 | F39: 0.51678766 | H39: 0.083192681 | I39: 0.10737775 | J39: 0.11769584 | K39: 0.039612008 | L39: 0.061611563 | M39: 0.064810273 | N39: 0.031590855 | O39: 0.041318427 | P39: 0.037430252 | Q39: 0.012469713 | S39: 0.023539147 | T39: 0.0054572337
B40: 55-64 | C40: 0.87649254 | E40: 0.74299648 | F40: 0.5063837 | H40: 0.057831982 | I40: 0.11969096 | J40: 0.11510909 | K40: 0.041564254 | L40: 0.052601214 | M40: 0.035965125 | N40: 0.021789167 | O40: 0.033586462 | P40: 0.021446213 | Q40: 0.0050492014 | S40: 0.028879973 | T40: 0.0035299728
B41: 65+ | C41: 0.75356774 | E41: 0.52295591 | F41: 0.34626201 | H41: 0.043929058 | I41: 0.13096964 | J41: 0.059702743 | K41: 0.085466462 | L41: 0.057262257 | M41: 0.0068751023 | N41: 0.057244935 | O41: 0.045653794 | P41: 0.0043502088 | Q41: 0.0046499924 | S41: 0.027996694 | T41: 0.0012937272
C42: Estimated number of participants
A43: All# | B43: Total | C43: 5015652.8 | E43: 4034411.7 | F43: 2924550.8 | H43: 807433.26 | I43: 659179.57 | J43: 647654.94 | K43: 430265.34 | L43: 406382.91 | M43: 365717.41 | N43: 375800.6 | O43: 282541.39 | P43: 265409.42 | Q43: 258066.14 | S43: 81733.768 | T43: 73495.111
B44: 15-17 | C44: 203601.17 | E44: 155972.06 | F44: 146377.21 | H44: 57038.365 | I44: 24129.027 | J44: 18397.452 | K44: 29504.091 | L44: 16300.509 | M44: 20881.17 | N44: 23008.677 | O44: 23747.771 | P44: 11003.933 | Q44: 65122.463 | S44: 5789.3979 | T44: 16407.466
B45: 18-24 | C45: 603392.95 | E45: 486885.3 | F45: 414529.31 | H45: 159301.79 | I45: 89284.177 | J45: 89381.075 | K45: 67335.123 | L45: 72960.831 | M45: 66857.487 | N45: 73832.837 | O45: 39857.355 | P45: 40149.746 | Q45: 81513.947 | S45: 2615.4722 | T45: 11695.379
B46: 25-34 | C46: 970562.03 | E46: 788706.19 | F46: 610140.58 | H46: 189687.91 | I46: 180782.21 | J46: 189502.32 | K46: 110129.14 | L46: 113838.58 | M46: 103958.62 | N46: 97481.197 | O46: 58293.655 | P46: 101262.74 | Q46: 61024.701 | S46: 10196.839 | T46: 17781.62
B47: 35-44 | C47: 896984.71 | E47: 722022.69 | F47: 497870.39 | H47: 132781.48 | I47: 115935.75 | J47: 140675.81 | K47: 60356.769 | L47: 64483.589 | M47: 74366.581 | N47: 60145.266 | O47: 39556.209 | P47: 50432.211 | Q47: 30070.039 | S47: 7442.7838 | T47: 11410.219
B48: 45-54 | C48: 769097.39 | E48: 643810.46 | F48: 431472.31 | H48: 91795.574 | I48: 79211.761 | J48: 82612.979 | K48: 40672.879 | L48: 45795.629 | M48: 55721.902 | N48: 33234.668 | O48: 36781.756 | P48: 38208.709 | Q48: 11926.473 | S48: 13112.611 | T48: 6398.6651
B49: 55-64 | C49: 652990.96 | E49: 555254.92 | F49: 376257 | H49: 64960.871 | I49: 66573.59 | J49: 65650.06 | K49: 32464.94 | L49: 35731.257 | M49: 26256.227 | N49: 24585.838 | O49: 34461.778 | P49: 17749.935 | Q49: 4367.3462 | S49: 14185.19 | T49: 3711.4322
...

Sheet 5
A8: =Index!A8 -> AusPlay survey results July 2024 - June 2025
A9: Released at: | C9: 13 November 2025
A10: Table number: | C10: 5
A11: Table name: | C11: Organised activity by type of entity (adults)
A12: Base: | C12: Adult population
E13: Type of entity organising the activity
C14: Total organised | E14: Sports club or association | F14: Gym/fitness club/sports/ leisure centre | G14: Private or commercial business | H14: Community organisation | I14: Individual personal trainer or coach | J14: Event (e.g. marathon, parkrun) | K14: Recreation club or association | L14: Less formal group (e.g. social group) | M14: Work | N14: Educational institution
C15: Participation rate
A16: All# | B16: Total | C16: 0.4340227 | E16: 0.13999695 | F16: 0.11429196 | G16: 0.11229376 | H16: 0.07460163 | I16: 0.070460771 | J16: 0.063409976 | K16: 0.065158253 | L16: 0.048988487 | M16: 0.046018059 | N16: 0.044744842
B17: 15-17 | C17: 0.60035271 | E17: 0.2369585 | F17: 0.10024092 | G17: 0.076429833 | H17: 0.12257092 | I17: 0.067718353 | J17: 0.086748114 | K17: 0.09558657 | L17: 0.098657037 | M17: 0.045714415 | N17: 0.27054284
B18: 18-24 | C18: 0.54981326 | E18: 0.23475734 | F18: 0.1315749 | G18: 0.13171769 | H18: 0.09922936 | I18: 0.10751977 | J18: 0.098525485 | K18: 0.10880481 | L18: 0.058736357 | M18: 0.059167243 | N18: 0.12012419
B19: 25-34 | C19: 0.535788 | E19: 0.17954233 | F19: 0.17111296 | G19: 0.17936667 | H19: 0.10423881 | I19: 0.10774985 | J19: 0.098398332 | K19: 0.092267354 | L19: 0.055175782 | M19: 0.09584664 | N19: 0.057760757
B20: 35-44 | C20: 0.44794668 | E20: 0.13209301 | F20: 0.11533463 | G20: 0.13994641 | H20: 0.060043821 | I20: 0.064149244 | J20: 0.073980993 | K20: 0.059833415 | L20: 0.039351112 | M20: 0.050170723 | N20: 0.029914127
B21: 45-54 | C21: 0.37302685 | E21: 0.10639953 | F21: 0.091813734 | G21: 0.09575606 | H21: 0.047143617 | I21: 0.053081357 | J21: 0.064586823 | K21: 0.038522045 | L21: 0.042633447 | M21: 0.044287416 | N21: 0.013823881
B22: 55-64 | C22: 0.33232764 | E22: 0.087067694 | F22: 0.089229238 | G22: 0.087991421 | H22: 0.043513078 | I22: 0.047890956 | J22: 0.03519148 | K22: 0.032952641 | L22: 0.04618946 | M22: 0.023790412 | N22: 0.005853597
B23: 65+ | C23: 0.33923695 | E23: 0.094991581 | F23: 0.087685353 | G23: 0.052167453 | H23: 0.076255294 | I23: 0.048632696 | J23: 0.015009001 | K23: 0.053931025 | L23: 0.042323838 | M23: 0.0056061834 | N23: 0.0034315428
A25: Males | B25: Total | C25: 0.42932234 | E25: 0.18163806 | F25: 0.091070638 | G25: 0.078125531 | H25: 0.081764683 | I25: 0.066107034 | J25: 0.067575349 | K25: 0.077478785 | L25: 0.051702894 | M25: 0.05583289 | N25: 0.052810091
B26: 15-17 | C26: 0.63562264 | E26: 0.22257342 | F26: 0.09403515 | G26: 0.051415591 | H26: 0.1248395 | I26: 0.068459882 | J26: 0.06572958 | K26: 0.1099877 | L26: 0.10863404 | M26: 0.020077156 | N26: 0.32323802
B27: 18-24 | C27: 0.54866345 | E27: 0.27517409 | F27: 0.11818611 | G27: 0.085346586 | H27: 0.11331675 | I27: 0.11238997 | J27: 0.10686851 | K27: 0.12110459 | L27: 0.070340582 | M27: 0.066141161 | N27: 0.1378947
B28: 25-34 | C28: 0.5343205 | E28: 0.23658044 | F28: 0.14903182 | G28: 0.12566921 | H28: 0.12918985 | I28: 0.10738437 | J28: 0.10475806 | K28: 0.12616724 | L28: 0.055862571 | M28: 0.12873199 | N28: 0.072929351
B29: 35-44 | C29: 0.43828293 | E29: 0.16994079 | F29: 0.10766307 | G29: 0.085458911 | H29: 0.069189835 | I29: 0.055336431 | J29: 0.075449248 | K29: 0.071573292 | L29: 0.040251034 | M29: 0.061794877 | N29: 0.038115179
B30: 45-54 | C30: 0.35865703 | E30: 0.13028131 | F30: 0.074921278 | G30: 0.07241366 | H30: 0.054393823 | I30: 0.045027298 | J30: 0.064154956 | K30: 0.044720538 | L30: 0.04101965 | M30: 0.050477972 | N30: 0.015362332
B31: 55-64 | C31: 0.32774677 | E31: 0.11694859 | F31: 0.057671053 | G31: 0.059791721 | H31: 0.045704863 | I31: 0.04202668 | J31: 0.034599581 | K31: 0.044360918 | L31: 0.059116485 | M31: 0.024967922 | N31: 0.0066940806
B32: 65+ | C32: 0.32990746 | E32: 0.15545086 | F32: 0.038188954 | G32: 0.043935348 | H32: 0.066322476 | I32: 0.039089322 | J32: 0.02463846 | K32: 0.050633666 | L32: 0.038886808 | M32: 0.007127369 | N32: 0.0020482624
A34: Females | B34: Total | C34: 0.44081507 | E34: 0.10122022 | F34: 0.13704474 | G34: 0.14576029 | H34: 0.068538912 | I34: 0.075082883 | J34: 0.059911789 | K34: 0.053768047 | L34: 0.045709409 | M34: 0.03665636 | N34: 0.03738591
B35: 15-17 | C35: 0.58978493 | E35: 0.25302513 | F35: 0.1071237 | G35: 0.096178931 | H35: 0.12393976 | I35: 0.068840541 | J35: 0.10389221 | K35: 0.087622685 | L35: 0.093931147 | M35: 0.065159479 | N35: 0.23946923
B36: 18-24 | C36: 0.5592312 | E36: 0.19070559 | F36: 0.14851089 | G36: 0.18821374 | H36: 0.085464764 | I36: 0.10506027 | J36: 0.09162214 | K36: 0.095795932 | L36: 0.043709877 | M36: 0.052668533 | N36: 0.10097588
B37: 25-34 | C37: 0.54083982 | E37: 0.1288957 | F37: 0.19299196 | G37: 0.23078626 | H37: 0.082425887 | I37: 0.10862464 | J37: 0.093794917 | K37: 0.061973862 | L37: 0.054435701 | M37: 0.065764888 | N37: 0.044425235
B38: 35-44 | C38: 0.46021792 | E38: 0.094782458 | F38: 0.12359365 | G38: 0.197611 | H38: 0.051364184 | I38: 0.072968448 | J38: 0.072295001 | K38: 0.048485878 | L38: 0.036882001 | M38: 0.038826464 | N38: 0.02184494
B39: 45-54 | C39: 0.38444102 | E39: 0.083192681 | F39: 0.10737775 | G39: 0.11769584 | H39: 0.039612008 | I39: 0.061611563 | J39: 0.064810273 | K39: 0.031590855 | L39: 0.041318427 | M39: 0.037430252 | N39: 0.012469713
B40: 55-64 | C40: 0.33596192 | E40: 0.057831982 | F40: 0.11969096 | G40: 0.11510909 | H40: 0.041564254 | I40: 0.052601214 | J40: 0.035965125 | K40: 0.021789167 | L40: 0.033586462 | M40: 0.021446213 | N40: 0.0050492014
B41: 65+ | C41: 0.3502837 | E41: 0.043929058 | F41: 0.13096964 | G41: 0.059702743 | H41: 0.085466462 | I41: 0.057262257 | J41: 0.0068751023 | K41: 0.057244935 | L41: 0.045653794 | M41: 0.0043502088 | N41: 0.0046499924
C42: Estimated number of participants
A43: All# | B43: Total | C43: 2503228.5 | E43: 807433.26 | F43: 659179.57 | G43: 647654.94 | H43: 430265.34 | I43: 406382.91 | J43: 365717.41 | K43: 375800.6 | L43: 282541.39 | M43: 265409.42 | N43: 258066.14
B44: 15-17 | C44: 144511.12 | E44: 57038.365 | F44: 24129.027 | G44: 18397.452 | H44: 29504.091 | I44: 16300.509 | J44: 20881.17 | K44: 23008.677 | L44: 23747.771 | M44: 11003.933 | N44: 65122.463
B45: 18-24 | C45: 373092.63 | E45: 159301.79 | F45: 89284.177 | G45: 89381.075 | H45: 67335.123 | I45: 72960.831 | J45: 66857.487 | K45: 73832.837 | L45: 39857.355 | M45: 40149.746 | N45: 81513.947
B46: 25-34 | C46: 566064.3 | E46: 189687.91 | F46: 180782.21 | G46: 189502.32 | H46: 110129.14 | I46: 113838.58 | J46: 103958.62 | K46: 97481.197 | L46: 58293.655 | M46: 101262.74 | N46: 61024.701
B47: 35-44 | C47: 450281.37 | E47: 132781.48 | F47: 115935.75 | G47: 140675.81 | H47: 60356.769 | I47: 64483.589 | J47: 74366.581 | K47: 60145.266 | L47: 39556.209 | M47: 50432.211 | N47: 30070.039
B48: 45-54 | C48: 321826.73 | E48: 91795.574 | F48: 79211.761 | G48: 82612.979 | H48: 40672.879 | I48: 45795.629 | J48: 55721.902 | K48: 33234.668 | L48: 36781.756 | M48: 38208.709 | N48: 11926.473
B49: 55-64 | C49: 247948.37 | E49: 64960.871 | F49: 66573.59 | G49: 65650.06 | H49: 32464.94 | I49: 35731.257 | J49: 26256.227 | K49: 24585.838 | L49: 34461.778 | M49: 17749.935 | N49: 4367.3462
...

Sheet 6
A8: =Index!A8 -> AusPlay survey results July 2024 - June 2025
A9: Released at: | C9: 13 November 2025
A10: Table number: | C10: 6
A11: Table name: | C11: Organised activity by type of entity (children)
A12: Base: | C12: Child population
E13: Type of entity organising the activity
C14: Total | E14: Sports club or association | F14: Private or commercial business | G14: Gym/fitness club/sports/ leisure centre | H14: Educational institution | I14: Recreation club or association | J14: Individual personal trainer or coach | K14: Community organisation | L14: Event (e.g. marathon, parkrun) | M14: Less formal group (e.g. social group)
C15: Participation rate
A16: All# | B16: Total | C16: 0.73214143 | E16: 0.29415288 | F16: 0.1708277 | G16: 0.15594189 | H16: 0.1263659 | I16: 0.11265287 | J16: 0.099630494 | K16: 0.11499198 | L16: 0.052779329 | M16: 0.07028996
A17: Age group | B17: 0-4 | C17: 0.49966693 | E17: 0.098603386 | F17: 0.13316321 | G17: 0.14868622 | H17: 0.045297035 | I17: 0.048907478 | J17: 0.05024255 | K17: 0.085186972 | L17: 0.039389435 | M17: 0.055258628
B18: 5-8 | C18: 0.82201643 | E18: 0.32769588 | F18: 0.20578539 | G18: 0.20090938 | H18: 0.12269435 | I18: 0.12397403 | J18: 0.11192861 | K18: 0.14080248 | L18: 0.044180848 | M18: 0.061101161
B19: 9-11 | C19: 0.85018509 | E19: 0.3975925 | F19: 0.19565946 | G19: 0.14635232 | H19: 0.18163684 | I19: 0.16642993 | J19: 0.1266067 | K19: 0.11845365 | L19: 0.063154941 | M19: 0.096953301
B20: 12-14 | C20: 0.84408334 | E20: 0.43871734 | F20: 0.1571134 | G20: 0.11765697 | H20: 0.19713724 | I20: 0.14002812 | J20: 0.13037661 | K20: 0.1220713 | L20: 0.073606028 | M20: 0.07865908
A22: Males | B22: Total | C22: 0.73432868 | E22: 0.32278295 | F22: 0.15094883 | G22: 0.1574399 | H22: 0.1381435 | I22: 0.12268576 | J22: 0.10715417 | K22: 0.10947546 | L22: 0.056342305 | M22: 0.076814972
A23: Age group | B23: 0-4 | C23: 0.47976559 | E23: 0.11411611 | F23: 0.12413615 | G23: 0.14626089 | H23: 0.053055219 | I23: 0.053310009 | J23: 0.037462122 | K23: 0.073634059 | L23: 0.035035104 | M23: 0.047568397
B24: 5-8 | C24: 0.82510263 | E24: 0.36274476 | F24: 0.16599271 | G24: 0.18855983 | H24: 0.14705215 | I24: 0.14682954 | J24: 0.1189951 | K24: 0.12899949 | L24: 0.046042366 | M24: 0.069324887
B25: 9-11 | C25: 0.87466939 | E25: 0.437334 | F25: 0.18068333 | G25: 0.17315266 | H25: 0.17681702 | I25: 0.16543615 | J25: 0.16368496 | K25: 0.12294735 | L25: 0.078118346 | M25: 0.11791003
B26: 12-14 | C26: 0.85830895 | E26: 0.46490221 | F26: 0.14435484 | G26: 0.12284995 | H26: 0.21182198 | I26: 0.15316695 | J26: 0.14014767 | K26: 0.1246716 | L26: 0.07862905 | M26: 0.089726259
A28: Females | B28: Total | C28: 0.73189896 | E28: 0.26173145 | F28: 0.19430339 | G28: 0.15493512 | H28: 0.1134849 | I28: 0.10170266 | J28: 0.09148733 | K28: 0.12181183 | L28: 0.048948258 | M28: 0.063154916
A29: Age group | B29: 0-4 | C29: 0.52100406 | E29: 0.077582083 | F29: 0.14406553 | G29: 0.15199915 | H29: 0.036470145 | I29: 0.043977354 | J29: 0.065207909 | K29: 0.09885014 | L29: 0.04456388 | M29: 0.064348641
B30: 5-8 | C30: 0.82368095 | E30: 0.29314518 | F30: 0.24844149 | G30: 0.21496086 | H30: 0.098059412 | I30: 0.10091098 | J30: 0.1052347 | K30: 0.15392815 | L30: 0.042504688 | M30: 0.052900635
B31: 9-11 | C31: 0.82780859 | E31: 0.35591493 | F31: 0.21324926 | G31: 0.11758231 | H31: 0.18794497 | I31: 0.16843395 | J31: 0.086389634 | K31: 0.11414184 | L31: 0.046990604 | M31: 0.074360998
B32: 12-14 | C32: 0.82821936 | E32: 0.40593457 | F32: 0.17427831 | G32: 0.11125396 | H32: 0.17859522 | I32: 0.12332128 | J32: 0.11803641 | K32: 0.11906802 | L32: 0.067283433 | M32: 0.064460245
C33: Estimated number of participants
A34: All# | B34: Total | C34: 895893.56 | E34: 359943.67 | F34: 209035.34 | G34: 190820.15 | H34: 154629.13 | I34: 137849.03 | J34: 121914.04 | K34: 140711.3 | L34: 64584.053 | M34: 86011.145
A35: Age group | B35: 0-4 | C35: 190197.74 | E35: 37533.284 | F35: 50688.45 | G35: 56597.267 | H35: 17242.273 | I35: 18616.585 | J35: 19124.778 | K35: 32426.339 | L35: 14993.551 | M35: 21034.144
B36: 5-8 | C36: 275470.33 | E36: 109815.92 | F36: 68961.844 | G36: 67327.819 | H36: 41116.761 | I36: 41545.601 | J36: 37508.995 | K36: 47185.074 | L36: 14805.681 | M36: 20475.937
B37: 9-11 | C37: 211466.22 | E37: 98893.032 | F37: 48666.304 | G37: 36402.157 | H37: 45178.463 | I37: 41396.053 | J37: 31490.837 | K37: 29462.931 | L37: 15708.505 | M37: 24115.158
B38: 12-14 | C38: 218759.28 | E38: 113701.44 | F38: 40718.744 | G38: 30492.905 | H38: 51091.637 | I38: 36290.79 | J38: 33789.427 | K38: 31636.96 | L38: 19076.317 | M38: 20385.906
A40: Males | B40: Total | C40: 478087.93 | E40: 210149.27 | F40: 98275.904 | G40: 102501.94 | H40: 89938.937 | I40: 79875.104 | J40: 69763.195 | K40: 71274.481 | L40: 36681.907 | M40: 50010.727
A41: Age group | B41: 0-4 | C41: 97826.679 | E41: 23268.864 | F41: 25312.003 | G41: 29823.35 | H41: 10818.233 | I41: 10870.186 | J41: 7638.7201 | K41: 15014.365 | L41: 7143.8385 | M41: 9699.4415
B42: 5-8 | C42: 140638.57 | E42: 61829.768 | F42: 28293.423 | G42: 32139.984 | H42: 25065.008 | I42: 25027.064 | J42: 20282.689 | K42: 21987.935 | L42: 7847.9116 | M42: 11816.412
B43: 9-11 | C43: 113824.18 | E43: 56911.999 | F43: 23513.035 | G43: 22533.038 | H43: 23009.896 | I43: 21528.859 | J43: 21300.969 | K43: 15999.623 | L43: 10165.849 | M43: 15344.097
B44: 12-14 | C44: 125798.5 | E44: 68138.637 | F44: 21157.443 | G44: 18005.568 | H44: 31045.8 | I44: 22448.995 | J44: 20540.816 | K44: 18272.558 | L44: 11524.308 | M44: 13150.776
A46: Females | B46: Total | C46: 417206.92 | E46: 149195.69 | F46: 110759.44 | G46: 88318.209 | H46: 64690.197 | I46: 57973.925 | J46: 52150.843 | K46: 69436.823 | L46: 27902.146 | M46: 36000.418
A47: Age group | B47: 0-4 | C47: 91772.349 | E47: 13665.709 | F47: 25376.447 | G47: 26773.917 | H47: 6424.0399 | I47: 7746.3986 | J47: 11486.058 | K47: 17411.975 | L47: 7849.7122 | M47: 11334.702
B48: 5-8 | C48: 134831.76 | E48: 47986.152 | F48: 40668.42 | G48: 35187.836 | H48: 16051.753 | I48: 16518.537 | J48: 17226.306 | K48: 25197.139 | L48: 6957.769 | M48: 8659.5247
B49: 9-11 | C49: 97642.039 | E49: 41981.033 | F49: 25153.27 | G49: 13869.119 | H49: 22168.567 | I49: 19867.194 | J49: 10189.868 | K49: 13463.308 | L49: 5542.6561 | M49: 8771.0609
B50: 12-14 | C50: 92960.778 | E50: 45562.8 | F50: 19561.3 | G50: 12487.337 | H50: 20045.838 | I50: 13841.795 | J50: 13248.611 | K50: 13364.401 | L50: 7552.0092 | M50: 7235.1297
A52: NB. Please note that for children 0-14 years, data was collected via the child's parent/guardian for organised participation outside of school hours
...

Sheet 7
A8: =Index!A8 -> AusPlay survey results July 2024 - June 2025
A9: Released at: | C9: 13 November 2025
A10: Table number: | C10: 7
A11: Table name: | C11: Places where activity took place (adults)
A12: Base: | C12: Adult population
C13: Total | E13: Public space | F13: Home environment | G13: Gym/fitness club/sports/ leisure centre | H13: Free community facilities | I13: Sports club or association facilities | J13: Private or commercial premises | K13: Recreation club or association facilities | L13: Educational institution facilities | M13: Workplace
C14: Participation rate
A15: All# | B15: Total | C15: 0.86963983 | E15: 0.62703703 | F15: 0.29549357 | G15: 0.29835973 | H15: 0.2169757 | I15: 0.20193379 | J15: 0.16610904 | K15: 0.099510054 | L15: 0.069293788 | M15: 0.065911354
B16: 15-17 | C16: 0.84583468 | E16: 0.58422972 | F16: 0.37406514 | G16: 0.26609016 | H16: 0.39331415 | I16: 0.34458279 | J16: 0.17584778 | K16: 0.16202015 | L16: 0.36541547 | M16: 0.07666368
B17: 18-24 | C17: 0.88919859 | E17: 0.56609598 | F17: 0.37605381 | G17: 0.42006251 | H17: 0.3353897 | I17: 0.31718209 | J17: 0.21279522 | K17: 0.15628244 | L17: 0.18563492 | M17: 0.076757978
B18: 25-34 | C18: 0.91865092 | E18: 0.61391422 | F18: 0.34294366 | G18: 0.42251939 | H18: 0.29742987 | I18: 0.2517973 | J18: 0.25458804 | K18: 0.13876205 | L18: 0.085954388 | M18: 0.11376044
B19: 35-44 | C19: 0.89233389 | E19: 0.61673064 | F19: 0.3085517 | G19: 0.31173778 | H19: 0.23864723 | I19: 0.1992741 | J19: 0.18836189 | K19: 0.087440176 | L19: 0.04370732 | M19: 0.070371314
B20: 45-54 | C20: 0.89145479 | E20: 0.67589523 | F20: 0.30970315 | G20: 0.26892717 | H20: 0.19173825 | I20: 0.15303572 | J20: 0.14424445 | K20: 0.080007511 | L20: 0.039322156 | M20: 0.079573834
B21: 55-64 | C21: 0.8752102 | E21: 0.71794333 | F21: 0.28428968 | G21: 0.22328741 | H21: 0.14237809 | I21: 0.14800542 | J21: 0.11914988 | K21: 0.04943658 | L21: 0.011035597 | M21: 0.048758624
B22: 65+ | C22: 0.78038467 | E22: 0.59808548 | F22: 0.17598716 | G22: 0.18114622 | H22: 0.08777447 | I22: 0.13389368 | J22: 0.084614377 | K22: 0.075119714 | L22: 0.0074891096 | M22: 0.011587873
A24: Males | B24: Total | C24: 0.87734998 | E24: 0.60583453 | F24: 0.28452822 | G24: 0.28988569 | H24: 0.21778531 | I24: 0.26775545 | J24: 0.135442 | K24: 0.11883481 | L24: 0.080959792 | M24: 0.074564253
B25: 15-17 | C25: 0.81985642 | E25: 0.53221396 | F25: 0.38261435 | G25: 0.23864255 | H25: 0.3685753 | I25: 0.38923716 | J25: 0.13502984 | K25: 0.22217576 | L25: 0.40633447 | M25: 0.078349892
B26: 18-24 | C26: 0.88133157 | E26: 0.50206537 | F26: 0.35917969 | G26: 0.39246395 | H26: 0.33672798 | I26: 0.37884498 | J26: 0.1632322 | K26: 0.1768267 | L26: 0.20860065 | M26: 0.084217691
B27: 25-34 | C27: 0.92020703 | E27: 0.55729311 | F27: 0.32358962 | G27: 0.42005016 | H27: 0.29521531 | I27: 0.32914636 | J27: 0.20989829 | K27: 0.17860662 | L27: 0.10887547 | M27: 0.1319037
B28: 35-44 | C28: 0.88795492 | E28: 0.57115815 | F28: 0.26708602 | G28: 0.32350652 | H28: 0.23505513 | I28: 0.27536128 | J28: 0.14277351 | K28: 0.10988589 | L28: 0.052051037 | M28: 0.075461071
B29: 45-54 | C29: 0.90325368 | E29: 0.65812874 | F29: 0.28811446 | G29: 0.26410211 | H29: 0.18895948 | I29: 0.18934193 | J29: 0.12043332 | K29: 0.097621428 | L29: 0.055441525 | M29: 0.092995354
B30: 55-64 | C30: 0.87325812 | E30: 0.72036098 | F30: 0.28157012 | G30: 0.21456907 | H30: 0.14718867 | I30: 0.20748331 | J30: 0.097106495 | K30: 0.055143934 | L30: 0.01054882 | M30: 0.050085252
B31: 65+ | C31: 0.81769266 | E31: 0.64741129 | F31: 0.19537323 | G31: 0.14901646 | H31: 0.092665473 | I31: 0.20917602 | J31: 0.078468379 | K31: 0.073741965 | L31: 0.0047807127 | M31: 0.01528187
A33: Females | B33: Total | C33: 0.8644377 | E33: 0.64898907 | F33: 0.30692033 | G33: 0.30750975 | H33: 0.21652181 | I33: 0.14014627 | J33: 0.1961154 | K33: 0.081658128 | L33: 0.058420125 | M33: 0.057479929
B34: 15-17 | C34: 0.88504676 | E34: 0.63567432 | F34: 0.37708011 | G34: 0.2922068 | H34: 0.42059845 | I34: 0.32106464 | J34: 0.20932173 | K34: 0.12296464 | L34: 0.34507628 | M34: 0.077328726
B35: 18-24 | C35: 0.90036213 | E35: 0.63777241 | F35: 0.39641405 | G35: 0.45974332 | H35: 0.33302777 | I35: 0.25025986 | J35: 0.277255 | K35: 0.13461099 | L35: 0.16035716 | M35: 0.065372572
B36: 25-34 | C36: 0.91694021 | E36: 0.66592015 | F36: 0.3620103 | G36: 0.42477469 | H36: 0.29974299 | I36: 0.18156392 | J36: 0.29617606 | K36: 0.10355994 | L36: 0.064922254 | M36: 0.09599776
B37: 35-44 | C37: 0.89883808 | E37: 0.66455456 | F37: 0.35278628 | G37: 0.30002398 | H37: 0.24303269 | I37: 0.12347378 | J37: 0.23650869 | K37: 0.064359395 | L37: 0.0356566 | M37: 0.065983363
B38: 45-54 | C38: 0.87860481 | E38: 0.69559132 | F38: 0.32987162 | G38: 0.27223335 | H38: 0.19455773 | I38: 0.11686815 | J38: 0.16489534 | K38: 0.062661474 | L38: 0.023921669 | M38: 0.067288786
B39: 55-64 | C39: 0.87649254 | E39: 0.71535388 | F39: 0.287191 | G39: 0.23312797 | H39: 0.13834778 | I39: 0.089678452 | J39: 0.14031381 | K39: 0.04402533 | L39: 0.011577489 | M39: 0.047697201
B40: 65+ | C40: 0.75356774 | E40: 0.55931807 | F40: 0.16091658 | G40: 0.2103553 | H40: 0.084360427 | I40: 0.070451664 | J40: 0.090648848 | K40: 0.076975007 | L40: 0.0098816697 | M40: 0.0085197738
C41: Estimated number of participants
A42: All# | B42: Total | C42: 5015652.8 | E42: 3616439.8 | F42: 1704260.9 | G42: 1720791.5 | H42: 1251408.6 | I42: 1164654.3 | J42: 958034.86 | K42: 573924.82 | L42: 399652.33 | M42: 380144.12
B43: 15-17 | C43: 203601.17 | E43: 140630.14 | F43: 90041.353 | G43: 64050.659 | H43: 94674.791 | I43: 82944.647 | J43: 42328.382 | K43: 38999.929 | L43: 87959.288 | M43: 18453.742
B44: 18-24 | C44: 603392.95 | E44: 384141.77 | F44: 255182.83 | G44: 285046.29 | H44: 227588.96 | I44: 215233.62 | J44: 144398.72 | K44: 106050.23 | L44: 125968.26 | M44: 52086.478
B45: 25-34 | C45: 970562.03 | E45: 648605.28 | F45: 362322.72 | G45: 446395.11 | H45: 314237.03 | I45: 266025.86 | J45: 268974.3 | K45: 146603.21 | L45: 90811.497 | M45: 120188.82
B46: 35-44 | C46: 896984.71 | E46: 619945.03 | F46: 310159.87 | G46: 313362.55 | H46: 239891.06 | I46: 200312.72 | J46: 189343.63 | K46: 87895.913 | L46: 43935.122 | M46: 70738.088
B47: 45-54 | C47: 769097.39 | E47: 583124.64 | F47: 267194.58 | G47: 232015.33 | H47: 165421.05 | I47: 132030.67 | J47: 124446.05 | K47: 69026.011 | L47: 33924.959 | M47: 68651.859
B48: 55-64 | C48: 652990.96 | E48: 535654.75 | F48: 212107.44 | G48: 166593.88 | H48: 106227.75 | I48: 110426.28 | J48: 88897.264 | K48: 36884.442 | L48: 8233.6167 | M48: 36378.621
B49: 65+ | C49: 919023.6 | E49: 704338.13 | F49: 207252.09 | G49: 213327.69 | H49: 103368.01 | I49: 157680.51 | J49: 99646.512 | K49: 88465.078 | L49: 8819.5845 | M49: 13646.513
...

Sheet 8
A8: =Index!A8 -> AusPlay survey results July 2024 - June 2025
A9: Released at: | C9: 13 November 2025
A10: Table number: | C10: 8
A11: Table name: | C11: Places where activity took place (children)
A12: Base: | C12: Child population
C13: Total | E13: Public space | F13: Home environment | G13: Gym/fitness club/sports/ leisure centre | H13: Free community facilities | I13: Sports club or association facilities | J13: Private or commercial premises | K13: Recreation club or association facilities | L13: Educational institution facilities
C14: Participation rate
A15: All# | B15: Total | C15: 0.73214143 | E15: 0.16234613 | F15: 0.11891082 | G15: 0.20081421 | H15: 0.14240245 | I15: 0.29566526 | J15: 0.17797343 | K15: 0.12133398 | L15: 0.15038405
B16: 0-4 | C16: 0.49966693 | E16: 0.11150203 | F16: 0.098760909 | G16: 0.1618736 | H16: 0.074227715 | I16: 0.098060484 | J16: 0.13290477 | K16: 0.059995077 | L16: 0.065457928
B17: 5-8 | C17: 0.82201643 | E17: 0.14030567 | F17: 0.11194928 | G17: 0.26936484 | H17: 0.15340182 | I17: 0.32500187 | J17: 0.23362004 | K17: 0.13168052 | L17: 0.15655241
B18: 9-11 | C18: 0.85018509 | E18: 0.23289398 | F18: 0.14399315 | G18: 0.21745909 | H18: 0.18339856 | I18: 0.41341775 | J18: 0.19722075 | K18: 0.1620703 | L18: 0.19585002
B19: 12-14 | C19: 0.84408334 | E19: 0.19781548 | F19: 0.13343518 | G19: 0.15339421 | H19: 0.18896546 | I19: 0.43495099 | J19: 0.15374176 | K19: 0.15895044 | L19: 0.22350733
A21: Males | B21: Total | C21: 0.73432868 | E21: 0.17448139 | F21: 0.12995241 | G21: 0.19887493 | H21: 0.16649166 | I21: 0.3231512 | J21: 0.14823442 | K21: 0.11327297 | L21: 0.15903373
B22: 0-4 | C22: 0.47976559 | E22: 0.10157533 | F22: 0.093280274 | G22: 0.15583289 | H22: 0.075052412 | I22: 0.11478137 | J22: 0.12172605 | K22: 0.053949786 | L22: 0.065355264
B23: 5-8 | C23: 0.82510263 | E23: 0.1468584 | F23: 0.12448969 | G23: 0.23950978 | H23: 0.18740012 | I23: 0.35880666 | J23: 0.18578473 | K23: 0.11844159 | L23: 0.17348412
B24: 9-11 | C24: 0.87466939 | E24: 0.25677135 | F24: 0.17782097 | G24: 0.25491328 | H24: 0.23922161 | I24: 0.4438144 | J24: 0.16374493 | K24: 0.14488231 | L24: 0.18820444
B25: 12-14 | C25: 0.85830895 | E25: 0.23496997 | F25: 0.14482243 | G25: 0.16174342 | H25: 0.20481212 | I25: 0.46443846 | J25: 0.12767233 | K25: 0.1617282 | L25: 0.2466557
A27: Females | B27: Total | C27: 0.73189896 | E27: 0.14816879 | F27: 0.1068368 | G27: 0.2039359 | H27: 0.11553235 | I27: 0.26560771 | J27: 0.21274299 | K27: 0.1300383 | L27: 0.14118402
B28: 0-4 | C28: 0.52100406 | E28: 0.11997316 | F28: 0.10544096 | G28: 0.16941651 | H28: 0.073525345 | I28: 0.079037741 | J28: 0.14629697 | K28: 0.063798047 | L28: 0.065799261
B29: 5-8 | C29: 0.82368095 | E29: 0.13431513 | F29: 0.099555669 | G29: 0.30205051 | H29: 0.11891075 | I29: 0.29173062 | J29: 0.28481588 | K29: 0.14624725 | L29: 0.13985096
B30: 9-11 | C30: 0.82780859 | E30: 0.20782074 | F30: 0.10745702 | G30: 0.17732273 | H30: 0.12281055 | I30: 0.38213643 | J30: 0.2352293 | K30: 0.18191722 | L30: 0.20535325
B31: 12-14 | C31: 0.82821936 | E31: 0.14993459 | F31: 0.11899439 | G31: 0.14298461 | H31: 0.16887996 | I31: 0.39784358 | J31: 0.18827721 | K31: 0.1558339 | L31: 0.19399821
C32: Estimated number of participants
A33: All# | B33: Total | C33: 895893.56 | E33: 198656.77 | F33: 145506.64 | G33: 245728.69 | H33: 174252.45 | I33: 361794.31 | J33: 217779.3 | K33: 148471.76 | L33: 184019.23
B34: 0-4 | C34: 190197.74 | E34: 42443.139 | F34: 37593.246 | G34: 61617.031 | H34: 28254.709 | I34: 37326.629 | J34: 50590.074 | K34: 22837.068 | L34: 24916.498
B35: 5-8 | C35: 275470.33 | E35: 47018.585 | F35: 37515.922 | G35: 90268.294 | H35: 51407.306 | I35: 108913.12 | J35: 78289.662 | K35: 44128.165 | L35: 52463.116
B36: 9-11 | C36: 211466.22 | E36: 57927.631 | F36: 35815.362 | G36: 54088.519 | H36: 45616.655 | I36: 102829.24 | J36: 49054.642 | K36: 40311.686 | L36: 48713.702
B37: 12-14 | C37: 218759.28 | E37: 51267.415 | F37: 34582.112 | G37: 39754.85 | H37: 48973.775 | I37: 112725.32 | J37: 39844.923 | K37: 41194.846 | L37: 57925.917
A39: Males | B39: Total | C39: 478087.93 | E39: 113596.88 | F39: 84606.09 | G39: 129478.4 | H39: 108395.13 | I39: 210389.02 | J39: 96508.673 | K39: 73746.869 | L39: 103539.61
B40: 0-4 | C40: 97826.679 | E40: 20711.735 | F40: 19020.329 | G40: 31775.13 | H40: 15303.574 | I40: 23404.513 | J40: 24820.569 | K40: 11000.64 | L40: 13326.276
B41: 5-8 | C41: 140638.57 | E41: 25031.983 | F41: 21219.241 | G41: 40824.392 | H41: 31942.311 | I41: 61158.52 | J41: 31666.968 | K41: 20188.344 | L41: 29570.331
B42: 9-11 | C42: 113824.18 | E42: 33414.669 | F42: 23140.544 | G42: 33172.87 | H42: 31130.853 | I42: 57755.319 | J42: 21308.774 | K42: 18854.106 | L42: 24491.786
B43: 12-14 | C43: 125798.5 | E43: 34438.497 | F43: 21225.975 | G43: 23706.009 | H43: 30018.396 | I43: 68070.667 | J43: 18712.362 | K43: 23703.779 | L43: 36151.222
A45: Females | B45: Total | C45: 417206.92 | E45: 84461.176 | F45: 60900.552 | G45: 116250.29 | H45: 65857.312 | I45: 151405.29 | J45: 121270.63 | K45: 74126.184 | L45: 80479.618
B46: 0-4 | C46: 91772.349 | E46: 21132.693 | F46: 18572.916 | G46: 29841.9 | H46: 12951.134 | I46: 13922.116 | J46: 25769.505 | K46: 11237.718 | L46: 11590.222
B47: 5-8 | C47: 134831.76 | E47: 21986.602 | F47: 16296.681 | G47: 49443.902 | H47: 19464.995 | I47: 47754.597 | J47: 46622.694 | K47: 23939.82 | L47: 22892.785
B48: 9-11 | C48: 97642.039 | E48: 24512.963 | F48: 12674.818 | G48: 20915.648 | H48: 14485.803 | I48: 45073.923 | J48: 27745.868 | K48: 21457.579 | L48: 24221.916
B49: 12-14 | C49: 92960.778 | E49: 16828.918 | F49: 13356.137 | G49: 16048.841 | H49: 18955.38 | I49: 44654.654 | J49: 21132.561 | K49: 17491.067 | L49: 21774.695
A51: NB. Please note that for children 0-14 years, data was collected via the child's parent/guardian for organised participation outside of school hours
A52: NB. Estimated participant numbers have not been rounded but users must remember that they are estimates and are subject to margins of error. Refer to sheet number 27 for margin of error and relative margin of error statistics.
...

Sheet 9
A8: =Index!A8 -> AusPlay survey results July 2024 - June 2025
A9: Released at: | C9: 13 November 2025
A10: Table number: | C10: 9
A11: Table name: | C11: Frequency of participation (adults)
A12: Base: | C12: Adult population
C13: 1+ per year | D13: 1+ per month | E13: 1+ per fortnight | F13: 1+ per week | G13: 2+ per week | H13: 3+ per week | I13: 4+ per week | J13: 5+ per week | K13: 6+ per week | L13: 7+ per week
C14: Participation rate
A15: All | B15: Total | C15: 0.86963983 | D15: 0.8171353 | E15: 0.77222214 | F15: 0.69587655 | G15: 0.59510744 | H15: 0.50051291 | I15: 0.40920595 | J15: 0.33822001 | K15: 0.25788474 | L15: 0.19587427
A16: Age group | B16: 15-17 | C16: 0.84583468 | D16: 0.77018314 | E16: 0.71914429 | F16: 0.64605555 | G16: 0.52918113 | H16: 0.44760347 | I16: 0.36008207 | J16: 0.31273713 | K16: 0.26277146 | L16: 0.20240423
B17: 18-24 | C17: 0.88919859 | D17: 0.83066302 | E17: 0.77873471 | F17: 0.6971593 | G17: 0.57879601 | H17: 0.47908839 | I17: 0.38622871 | J17: 0.32851292 | K17: 0.24805689 | L17: 0.18406607
B18: 25-34 | C18: 0.91865092 | D18: 0.85615696 | E18: 0.80734147 | F18: 0.72103126 | G18: 0.61186879 | H18: 0.51492309 | I18: 0.42246992 | J18: 0.34196081 | K18: 0.2595666 | L18: 0.20817463
B19: 35-44 | C19: 0.89233389 | D19: 0.82789501 | E19: 0.77271705 | F19: 0.69155327 | G19: 0.58077596 | H19: 0.4702791 | I19: 0.36475184 | J19: 0.29188362 | K19: 0.21708316 | L19: 0.16408618
B20: 45-54 | C20: 0.89145479 | D20: 0.8419701 | E20: 0.79728021 | F20: 0.72534802 | G20: 0.62578542 | H20: 0.53644837 | I20: 0.44874346 | J20: 0.37526799 | K20: 0.29216316 | L20: 0.21914411
B21: 55-64 | C21: 0.8752102 | D21: 0.83729241 | E21: 0.803058 | F21: 0.74021626 | G21: 0.65275286 | H21: 0.5777315 | I21: 0.48286978 | J21: 0.39903712 | K21: 0.30256411 | L21: 0.22941298
B22: 65+ | C22: 0.78038467 | D22: 0.74378146 | E22: 0.70949621 | F22: 0.63676215 | G22: 0.55618191 | H22: 0.46130398 | I22: 0.38289755 | J22: 0.31954595 | K22: 0.24244849 | L22: 0.17914637
A24: Males | B24: Total | C24: 0.87734998 | D24: 0.82369864 | E24: 0.77541357 | F24: 0.69330247 | G24: 0.57997334 | H24: 0.48381292 | I24: 0.39295092 | J24: 0.32568054 | K24: 0.24716663 | L24: 0.18701729
A25: Age group | B25: 15-17 | C25: 0.81985642 | D25: 0.76870371 | E25: 0.71728812 | F25: 0.6328725 | G25: 0.51293749 | H25: 0.46141719 | I25: 0.36547742 | J25: 0.33164125 | K25: 0.24886738 | L25: 0.2158319
B26: 18-24 | C26: 0.88133157 | D26: 0.81576551 | E26: 0.75887877 | F26: 0.6706821 | G26: 0.53759604 | H26: 0.43906984 | I26: 0.34632798 | J26: 0.29211479 | K26: 0.22443824 | L26: 0.16090224
B27: 25-34 | C27: 0.92020703 | D27: 0.85706581 | E27: 0.80032161 | F27: 0.69533249 | G27: 0.57593665 | H27: 0.47116949 | I27: 0.36689149 | J27: 0.28950747 | K27: 0.20937656 | L27: 0.16246799
